Workbook

Sheet Roadmap
A1: Done | B1: Day | C1: Pattern | D1: # | E1: Problem | F1: Difficulty | G1: URL | H1: Notes
B2: Hey, I'm Shubham, 7+ years in tech, 100+ interviews on both sides of the table. Career path: Infosys → Pubmatic → Amazon → Coursera (currently WFH) I've cracked multiple high-paying offers across India and internationally using the exact playbook below. Connect here - Linkedin , Instagram, Connect on - Whatsapp
A3: ☐ | B3: 1 | C3: Arrays | D3: 1 | E3: Contains Duplicate | F3: Easy | G3: https://leetcode.com/problems/contains-duplicate/
A4: ☐ | B4: 1 | C4: Arrays | D4: 2 | E4: Product of Array Except Self | F4: Medium | G4: https://leetcode.com/problems/product-of-array-except-self/
A5: ☐ | B5: 1 | C5: Arrays | D5: 3 | E5: Valid Sudoku | F5: Medium | G5: https://leetcode.com/problems/valid-sudoku/
A6: ☐ | B6: 2 | C6: Hashing | D6: 4 | E6: Valid Anagram | F6: Easy | G6: https://leetcode.com/problems/valid-anagram/
A7: ☐ | B7: 2 | C7: Hashing | D7: 5 | E7: Two Sum | F7: Easy | G7: https://leetcode.com/problems/two-sum/
A8: ☐ | B8: 2 | C8: Hashing | D8: 6 | E8: Group Anagrams | F8: Medium | G8: https://leetcode.com/problems/group-anagrams/
A9: ☐ | B9: 3 | C9: Hashing | D9: 7 | E9: Top K Frequent Elements | F9: Medium | G9: https://leetcode.com/problems/top-k-frequent-elements/
A10: ☐ | B10: 3 | C10: Hashing | D10: 8 | E10: Longest Consecutive Sequence | F10: Medium | G10: https://leetcode.com/problems/longest-consecutive-sequence/
A11: ☐ | B11: 4 | C11: Hashing | D11: 9 | E11: Subarray Sum Equals K | F11: Medium | G11: https://leetcode.com/problems/subarray-sum-equals-k/
A12: ☐ | B12: 5 | C12: Two Pointers | D12: 10 | E12: Valid Palindrome | F12: Easy | G12: https://leetcode.com/problems/valid-palindrome/
A13: ☐ | B13: 5 | C13: Two Pointers | D13: 11 | E13: Two Sum II - Input Array Is Sorted | F13: Medium | G13: https://leetcode.com/problems/two-sum-ii-input-array-is-sorted/
A14: ☐ | B14: 6 | C14: Two Pointers | D14: 12 | E14: Sort Colors | F14: Medium | G14: https://leetcode.com/problems/sort-colors/
A15: ☐ | B15: 6 | C15: Two Pointers | D15: 13 | E15: 3Sum | F15: Medium | G15: https://leetcode.com/problems/3sum/
A16: ☐ | B16: 7 | C16: Review | E16: Review Day: redo Days 1-6
A17: ☐ | B17: 8 | C17: Two Pointers | D17: 14 | E17: Container With Most Water | F17: Medium | G17: https://leetcode.com/problems/container-with-most-water/
A18: ☐ | B18: 8 | C18: Two Pointers | D18: 15 | E18: Trapping Rain Water | F18: Hard | G18: https://leetcode.com/problems/trapping-rain-water/
A19: ☐ | B19: 9 | C19: Sliding Window | D19: 16 | E19: Best Time to Buy and Sell Stock | F19: Easy | G19: https://leetcode.com/problems/best-time-to-buy-and-sell-stock/
A20: ☐ | B20: 9 | C20: Sliding Window | D20: 17 | E20: Longest Substring Without Repeating Characters | F20: Medium | G20: https://leetcode.com/problems/longest-substring-without-repeating-characters/
A21: ☐ | B21: 10 | C21: Sliding Window | D21: 18 | E21: Longest Repeating Character Replacement | F21: Medium | G21: https://leetcode.com/problems/longest-repeating-character-replacement/
A22: ☐ | B22: 10 | C22: Sliding Window | D22: 19 | E22: Permutation in String | F22: Medium | G22: https://leetcode.com/problems/permutation-in-string/
A23: ☐ | B23: 11 | C23: Sliding Window | D23: 20 | E23: Find All Anagrams in a String | F23: Medium | G23: https://leetcode.com/problems/find-all-anagrams-in-a-string/
A24: ☐ | B24: 11 | C24: Sliding Window | D24: 21 | E24: Minimum Window Substring | F24: Hard | G24: https://leetcode.com/problems/minimum-window-substring/
A25: ☐ | B25: 12 | C25: Sliding Window | D25: 22 | E25: Sliding Window Maximum | F25: Hard | G25: https://leetcode.com/problems/sliding-window-maximum/
A26: ☐ | B26: 13 | C26: Stack | D26: 23 | E26: Valid Parentheses | F26: Easy | G26: https://leetcode.com/problems/valid-parentheses/
A27: ☐ | B27: 13 | C27: Stack | D27: 24 | E27: Implement Queue using Stacks | F27: Easy | G27: https://leetcode.com/problems/implement-queue-using-stacks/
A28: ☐ | B28: 13 | C28: Stack | D28: 25 | E28: Min Stack | F28: Medium | G28: https://leetcode.com/problems/min-stack/
A29: ☐ | B29: 14 | C29: Review | E29: Review Day: redo Days 8-13
A30: ☐ | B30: 15 | C30: Stack | D30: 26 | E30: Evaluate Reverse Polish Notation | F30: Medium | G30: https://leetcode.com/problems/evaluate-reverse-polish-notation/
A31: ☐ | B31: 15 | C31: Stack | D31: 27 | E31: Daily Temperatures | F31: Medium | G31: https://leetcode.com/problems/daily-temperatures/
A32: ☐ | B32: 16 | C32: Stack | D32: 28 | E32: Generate Parentheses | F32: Medium | G32: https://leetcode.com/problems/generate-parentheses/
A33: ☐ | B33: 16 | C33: Stack | D33: 29 | E33: Car Fleet | F33: Medium | G33: https://leetcode.com/problems/car-fleet/
A34: ☐ | B34: 17 | C34: Stack | D34: 30 | E34: Largest Rectangle in Histogram | F34: Hard | G34: https://leetcode.com/problems/largest-rectangle-in-histogram/
A35: ☐ | B35: 18 | C35: Binary Search | D35: 31 | E35: Binary Search | F35: Easy | G35: https://leetcode.com/problems/binary-search/
A36: ☐ | B36: 18 | C36: Binary Search | D36: 32 | E36: Find First and Last Position in Sorted Array | F36: Medium | G36: https://leetcode.com/problems/find-first-and-last-position-of-element-in-sorted-array/
A37: ☐ | B37: 19 | C37: Binary Search | D37: 33 | E37: Search a 2D Matrix | F37: Medium | G37: https://leetcode.com/problems/search-a-2d-matrix/
A38: ☐ | B38: 19 | C38: Binary Search | D38: 34 | E38: Koko Eating Bananas | F38: Medium | G38: https://leetcode.com/problems/koko-eating-bananas/
A39: ☐ | B39: 20 | C39: Binary Search | D39: 35 | E39: Find Minimum in Rotated Sorted Array | F39: Medium | G39: https://leetcode.com/problems/find-minimum-in-rotated-sorted-array/
A40: ☐ | B40: 20 | C40: Binary Search | D40: 36 | E40: Search in Rotated Sorted Array | F40: Medium | G40: https://leetcode.com/problems/search-in-rotated-sorted-array/
...

Sheet Progress
A1: Progress Tracker
A3: Problems solved | B3: =COUNTIFS(Roadmap!$A$3:$A$165,"☑",Roadmap!$D$3:$D$165,">0") -> 0
A4: Total problems | B4: =COUNTIF(Roadmap!$D$3:$D$165,">0") -> 150
A5: Completion | B5: =IF(B4=0,0,B3/B4) -> 0
A6: Days completed (all rows in day ticked) | B6: =SUMPRODUCT(--(COUNTIFS(Roadmap!$B$3:$B$165,ROW($1:$90),Roadmap!$A$3:$A$165,"☑")=COUNTIF(Roadmap!$B$3:$B$165,ROW($1:$90)))) -> 0
A8: Pattern | B8: Solved | C8: Total | D8: Completion
A9: Arrays | B9: =COUNTIFS(Roadmap!$C$3:$C$165,A9,Roadmap!$A$3:$A$165,"☑",Roadmap!$D$3:$D$165,">0") -> 0 | C9: =COUNTIFS(Roadmap!$C$3:$C$165,A9,Roadmap!$D$3:$D$165,">0") -> 3 | D9: =IF(C9=0,0,B9/C9) -> 0
A10: Hashing | B10: =COUNTIFS(Roadmap!$C$3:$C$165,A10,Roadmap!$A$3:$A$165,"☑",Roadmap!$D$3:$D$165,">0") -> 0 | C10: =COUNTIFS(Roadmap!$C$3:$C$165,A10,Roadmap!$D$3:$D$165,">0") -> 6 | D10: =IF(C10=0,0,B10/C10) -> 0
A11: Two Pointers | B11: =COUNTIFS(Roadmap!$C$3:$C$165,A11,Roadmap!$A$3:$A$165,"☑",Roadmap!$D$3:$D$165,">0") -> 0 | C11: =COUNTIFS(Roadmap!$C$3:$C$165,A11,Roadmap!$D$3:$D$165,">0") -> 6 | D11: =IF(C11=0,0,B11/C11) -> 0
A12: Sliding Window | B12: =COUNTIFS(Roadmap!$C$3:$C$165,A12,Roadmap!$A$3:$A$165,"☑",Roadmap!$D$3:$D$165,">0") -> 0 | C12: =COUNTIFS(Roadmap!$C$3:$C$165,A12,Roadmap!$D$3:$D$165,">0") -> 7 | D12: =IF(C12=0,0,B12/C12) -> 0
A13: Stack | B13: =COUNTIFS(Roadmap!$C$3:$C$165,A13,Roadmap!$A$3:$A$165,"☑",Roadmap!$D$3:$D$165,">0") -> 0 | C13: =COUNTIFS(Roadmap!$C$3:$C$165,A13,Roadmap!$D$3:$D$165,">0") -> 8 | D13: =IF(C13=0,0,B13/C13) -> 0
A14: Binary Search | B14: =COUNTIFS(Roadmap!$C$3:$C$165,A14,Roadmap!$A$3:$A$165,"☑",Roadmap!$D$3:$D$165,">0") -> 0 | C14: =COUNTIFS(Roadmap!$C$3:$C$165,A14,Roadmap!$D$3:$D$165,">0") -> 8 | D14: =IF(C14=0,0,B14/C14) -> 0
A15: Linked List | B15: =COUNTIFS(Roadmap!$C$3:$C$165,A15,Roadmap!$A$3:$A$165,"☑",Roadmap!$D$3:$D$165,">0") -> 0 | C15: =COUNTIFS(Roadmap!$C$3:$C$165,A15,Roadmap!$D$3:$D$165,">0") -> 12 | D15: =IF(C15=0,0,B15/C15) -> 0
A16: Trees | B16: =COUNTIFS(Roadmap!$C$3:$C$165,A16,Roadmap!$A$3:$A$165,"☑",Roadmap!$D$3:$D$165,">0") -> 0 | C16: =COUNTIFS(Roadmap!$C$3:$C$165,A16,Roadmap!$D$3:$D$165,">0") -> 15 | D16: =IF(C16=0,0,B16/C16) -> 0
A17: Heap / Priority Queue | B17: =COUNTIFS(Roadmap!$C$3:$C$165,A17,Roadmap!$A$3:$A$165,"☑",Roadmap!$D$3:$D$165,">0") -> 0 | C17: =COUNTIFS(Roadmap!$C$3:$C$165,A17,Roadmap!$D$3:$D$165,">0") -> 7 | D17: =IF(C17=0,0,B17/C17) -> 0
A18: Backtracking | B18: =COUNTIFS(Roadmap!$C$3:$C$165,A18,Roadmap!$A$3:$A$165,"☑",Roadmap!$D$3:$D$165,">0") -> 0 | C18: =COUNTIFS(Roadmap!$C$3:$C$165,A18,Roadmap!$D$3:$D$165,">0") -> 9 | D18: =IF(C18=0,0,B18/C18) -> 0
A19: Tries | B19: =COUNTIFS(Roadmap!$C$3:$C$165,A19,Roadmap!$A$3:$A$165,"☑",Roadmap!$D$3:$D$165,">0") -> 0 | C19: =COUNTIFS(Roadmap!$C$3:$C$165,A19,Roadmap!$D$3:$D$165,">0") -> 3 | D19: =IF(C19=0,0,B19/C19) -> 0
A20: Graphs | B20: =COUNTIFS(Roadmap!$C$3:$C$165,A20,Roadmap!$A$3:$A$165,"☑",Roadmap!$D$3:$D$165,">0") -> 0 | C20: =COUNTIFS(Roadmap!$C$3:$C$165,A20,Roadmap!$D$3:$D$165,">0") -> 16 | D20: =IF(C20=0,0,B20/C20) -> 0
... A26: Bit Manipulation | B26: =COUNTIFS(Roadmap!$C$3:$C$165,A26,Roadmap!$A$3:$A$165,"☑",Roadmap!$D$3:$D$165,">0") -> 0 | C26: =COUNTIFS(Roadmap!$C$3:$C$165,A26,Roadmap!$D$3:$D$165,">0") -> 7 | D26: =IF(C26=0,0,B26/C26) -> 0
A28: Difficulty | B28: Solved | C28: Total | D28: Completion
A29: Easy | B29: =COUNTIFS(Roadmap!$F$3:$F$165,A29,Roadmap!$A$3:$A$165,"☑") -> 0 | C29: =COUNTIF(Roadmap!$F$3:$F$165,A29) -> 29 | D29: =IF(C29=0,0,B29/C29) -> 0
A30: Medium | B30: =COUNTIFS(Roadmap!$F$3:$F$165,A30,Roadmap!$A$3:$A$165,"☑") -> 0 | C30: =COUNTIF(Roadmap!$F$3:$F$165,A30) -> 101 | D30: =IF(C30=0,0,B30/C30) -> 0
A31: Hard | B31: =COUNTIFS(Roadmap!$F$3:$F$165,A31,Roadmap!$A$3:$A$165,"☑") -> 0 | C31: =COUNTIF(Roadmap!$F$3:$F$165,A31) -> 20 | D31: =IF(C31=0,0,B31/C31) -> 0
A33: How to use: on the Roadmap sheet, click a cell in the Done column and pick ☑ from the dropdown. Rows turn green and this sheet updates automatically.
